Workbook

Sheet Catalogos
A1: Periodos | B1: Cursos | D1: titpo de sangre | E1: NUCLEO ESTRUCTURANTE | F1: OBJETIVOS
A3: ABRIL 2023 - AGOSTO 2023 | B3: PRIMERO | C3: 1ro | D3: A+ | E3: FUNDAMENTOS DE PROGRAMACIÓN | F3: Aplicar de forma autónoma la lógica de programación para el desarrollo de algoritmos sencillos utilizando una sintaxis adecuada.
A4: OCTUBRE 2023- MARZO 2024 | B4: SEGUNDO | C4: 2do | D4: A- | E4: PROGRAMACIÓN ORIENTADA A OBJETOS | F4: Desarrollar aplicaciones de mediana complejidad aplicando el entorno de programación orientado a objetos. La codificación de los conceptos de la programación orientada a objetos se la realizará en el lenguaje Java.
A5: ABRIL 2023 - AGOSTO 2024 | B5: TERCERO | C5: 3ro | D5: B+ | E5: PROGRAMACIÓN WEB, TRABAJO DE INTEGRACIÓN CURRICULAR | F5: Aplica conceptos, técnicas, herramientas de programación, que contribuyan con la implementación de soluciones de Software
A6: SEPTIEMBRE 2024- MARZO 2025 | B6: CUARTO | C6: 4to | D6: B- | E6: DESARROLLO WEB - BACK- END | F6: Diseña una servicio web consumible por un cliente web
A7: ABRIL - SEPTIEMBRE 2024 | B7: QUINTO | C7: 5to | D7: AB+ | E7: APLICACIONES MÓVILES HÍBRIDAS AVANZADA S | F7: Aplica los conceptos de la técnología móvil híbrida
A8: 2025-II | D8: AB-
D9: O+
D10: O-

Sheet DATOS
C1: IMPORTANTE: Antes de enviar a su tutor académico, favor actualizar las celdas marcadas con color rojo y verificar que toda la información esté correcta y sin faltas de ortografía en todo el documento.
A3: AMAUTATECH
A4: DATOS DEL ESTUDIANTE
A6: Apellidos y Nombres Completos: | C6: VALLEJOS ALMACHI MARLON VINICIO
A7: Cédula: | C7: 1722586631
A8: Carrera: | C8: DESARROLLO DE SOFTWARE
A9: Nivel: | C9: TERCER | D9: =IF(C9="PRIMERO","1ro",IF(C9="SEGUNDO","2do",IF(C9="TERCER","3ro",IF(C9="CUARTO","4to","5to")))) -> 3ro
A10: E-mail: | C10: mva.vallejos@yavirac.edu.ec
A11: Teléfono: | C11: 0999294011
A12: Estado Civil | C12: SOLTERO | D12: Tipo de sangre: | E12: O+
A13: Domicilio | C13: Av.Ajavi y Jose Maria Aleman | D13: Contacto de emergencia: | E13: Mamá | F13: Telf. de emergencia: | H13: 0987355363
A14: DATOS DE LA CARRERA
A15: Coordinador de Carrera: | C15: MSc. Raúl Páez
A16: Docente Tutor | C16: Ing. Diego Yanez | E16: Cédula:
A19: Periodo Académico: | C19: 2025-II
A22: DATOS DEL PROYECTO EMPRESARIAL
A23: Nombre del Proyecto:
A24: EXPLORACIÓN DE LA ARQUITECTURA DEL PROYECTO YAVIGESTIÓN
A27: Cobertura y Localización: | C27: Sierra, Pichincha, Quito, Turubamba
A28: Plazo de Ejecución: | C28: 5 AÑOS
A30: Fecha Inicio: | B30: =IF(D$9="1ro",A76,IF(D$9="2do",A76,IF(D$9="3ro",A76,IF(C$30="4to",B$76,IF(C$30="5to",B$76))))) -> 45985 | C30: =D$9 -> 3ro | D30: 45810 | E30: 45870
A31: Fecha Final: | B31: =IF(D$9="1ro",A116,IF(D$9="2do",A116,IF(D$9="3ro",A116,IF(C$30="4to",B$111,IF(C$30="5to",B$111))))) -> 46045 | D31: 45817 | E31: Segundo Nivel
A32: INFORME FINAL | B32: =IF(C$30="1ro",A$116,IF(C$30="2do",A$116,IF(C$30="3ro",A$116,IF(C$30="4to",B$111,IF(C$30="5to",B$111))))) -> 46045
A35: DATOS DE LA EMPRESA BENEFICIARIA
A36: Razón Social: | C36: INSTITUTO DE CAPACITACIÓN Y ESPECIALIZACIÓN AMAUTA-TECH S.A.S. B.I.C.
A37: Representante legal: | C37: GUARDERAS RIOFRIO ESTEBAN | E37: Cargo: | F37: REPRESENTANTE LEGAL
A38: Tutor empresarial: | C38: Mauricio Tamayo
A39: Dirección: | C39: CLEMENTE CONCHA Numero: OE-758 Intersección: PASAJE E
A40: Teléfono: | C40: 0994287989
A41: E-mail: | C41: ice.am autatech@gmail.com
A42: Provincia: | C42: Pichincha
A43: Cantón: | C43: Quito
A44: Parroquia: | C44: Itchimbia
A47: NO IMPRIMIR ESTE DOCUMENTO ES SOLAMENTE INFORMATIVO
A52: SOLTERO
A53: CASADO
A54: DIVORCIADO
A55: UNIÓN LIBRE
A56: Noviembre 2019 - Abril 2020
A57: Mayo 2020 - Octubre 2020
...

Sheet A. Carta Compromiso
B1: INSTITUTO SUPERIOR TECNOLÓGICO DE TURISMO Y PATRIMONIO YAVIRAC | F1: 010201
B2: MACROPROCESO 01 DOCENCIA
B3: PROCESO 02 PROCESO DE FORMACIÓN PRÁCTICA EN EL ENTORNO LABORAL REAL - FORMACIÓN DUAL
B4: FORMATO 01 CARTA DE PRESENTACIÓN Y ACTA COMPROMISO ESTUDIANTES
A6: D.M. Quito, | B6: =DATOS!B30 -> 45985
A8: Yo, | B8: =DATOS!C6 -> VALLEJOS ALMACHI MARLON VINICIO | C8: con C.C. | D8: =DATOS!C7 -> 1722586631 | E8: estudiante de | F8: =+DATOS!D9 -> 3ro
A9: de la carrera | B9: =+DATOS!C8 -> DESARROLLO DE SOFTWARE | E9: en modalidad dual,
A10: DEL INSTITUTO SUPERIOR TECNOLÓGICO DE TURISMO Y PATRIMONIO YAVIRAC, | D10: asignado/a a
A11: =+DATOS!C36 -> INSTITUTO DE CAPACITACIÓN Y ESPECIALIZACIÓN AMAUTA-TECH S.A.S. B.I.C.
A12: De acuerdo con el proyecto de carrera aprobado y vigente, en cumplimiento del currículo de la carrera, y en el marco del convenio firmado, me presento y, expreso mi interés y predisposición de realizar prácticas de formación dual, con el fin de cumplir con la planificación, ejecución, control y evaluación del proceso de desarrollo de las competencias laborales como estudiante de la carrera. Soy una persona que cumple con el perfil de ingreso de la carrera, y busco aprender y desarrollar los conocimientos, habilidades-destrezas y actitudes del perfil de egreso, y lograr las competencias como profesional de mi carrera. Por lo cual, solicito su aceptación para realizar mi proceso de formación práctica en el entorno laboral real en modalidad dual.
A13: A la vez que, me comprometo con acatar la normativa general vigente con las obligaciones establecidas en el Artículo 16 (Obligaciones generales del estudiante en modalidad dual) del Reglamento para Carreras y Programas en Modalidad de Formación Dual vigente, así como también, la normativa interna de la entidad formadora y, la normativa del Instituto. Reconociendo y aceptando entre otras prohibiciones expresas durante la Fase Práctica, las que se determinan a continuación: • Prohibición de consumo de alcohol. • Prohibición de consumo de sustancias estupefacientes, psicotrópicos y estimulantes. • Prohibición de tratos groseros e irrespetuosos a compañeros y del entorno (compañeros y demás personas involucradas) • Prohibición de desacatar las directrices de tutores empresariales y también de tutores académicos del instituto.
A14: También me comprometo en: * Garantizar la confidencialidad, reserva y protección de los datos e información proporcionados por la entidad receptora formadora, durante y después de mi fase práctica. * Y, promover un entorno social armónico, precautelar y salvaguardar la propiedad ajena y los bienes que pertenecen al sitio.
A15: Y así mismo, me comprometo en elaborar y presentar todos los documentos necesarios para validar el proceso de formación en modalidad dual, de acuerdo con lo establecido por la entidad receptora formadora y/o el Instituto, los cuáles deberán estar correctamente llenados y firmados.
A16: El incumplimiento a lo comprometido con la entidad receptora formadora y/o del Instituto, será causal para la toma de medidas disciplinarias conforme a las responsabilidades del proceso de formación en modalidad dual . De no dar cumplimiento con lo antes citado, puede conllevar bajo el debido proceso a la pérdida de la fase práctica.
A18: De manera libre y voluntaria acepto lo expresado y firmo como esta acta compromiso como constancia.
B21: Estudiante | C21: Firma
B23: =DATOS!C6 -> VALLEJOS ALMACHI MARLON VINICIO

Sheet C. Curriculum estandarizado
B1: INSTITUTO SUPERIOR TECNOLÓGICO DE TURISMO Y PATRIMONIO YAVIRAC | I1: 010202
B2: MACROPROCESO 01 DOCENCIA
B3: PROCESO 02 PROCESO DE FORMACIÓN PRÁCTICA EN EL ENTORNO LABORAL REAL - FORMACIÓN DUAL
B4: FORMATO 02 CURRÍCULO ESTANDARIZADO
A6: INSTITUTO SUPERIOR TECNOLÓGICO DE TURISMO Y PATRIMONIO "YAVIRAC"
A7: CÓDIGO: | C7: =DATOS!C7 -> 1722586631
A8: PERIODO ACADÉMICO: | C8: =DATOS!C19 -> 2025-II
A9: 1. DATOS PERSONALES
A11: Nombres y apellidos: | C11: =DATOS!C6 -> VALLEJOS ALMACHI MARLON VINICIO
A12: # identificación: | C12: =DATOS!C7 -> 1722586631
A13: Estado civil: | C13: =DATOS!C12 -> SOLTERO
A14: Teléfono: | C14: =DATOS!C11 -> 0999294011
A15: Domicilio: | C15: =DATOS!C13 -> Av.Ajavi y Jose Maria Aleman
A17: Email institucional: | C17: =DATOS!C10 -> mva.vallejos@yavirac.edu.ec
A19: 2. DATOS ACADÉMICOS
A20: AÑO | B20: INSTITUCIÓN | F20: TITULO O MENCIÓN | H20: NOTA FINAL
A21: 2020 | B21: Institucion Educativa "Gonzalo Escudero" | F21: INFORMÁTICA | H21: 7.5
A23: 3. EXPERIENCIA LABORAL
A24: AÑO | B24: INSTITUCIÓN O EMPRESA | F24: CARGO | H24: ACTIVIDADES DESARROLLADAS
A25: 2019 | B25: Creditos Cofasa | F25: Auxiliar de ventas | H25: Detectar posbiles clientes
A26: 2024 | B26: Control Risk | F26: Guardia de seguridad | H26: Proteger las instalaciones del C.C
A27: 2025 | B27: El español | F27: Servicio al cliente | H27: Personal Polifuncional
A29: 4. PRÁCTICAS DUALES
A30: AÑO | B30: INSTITUCIÓN O EMPRESA | F30: PUESTO DE APRENDIZAJE | H30: ACTIVIDADES DESARROLLADAS
A31: 2020 | B31: COMANDANCIA GENERAL DEL EJERCITO | F31: Pasante de soporte técnico | H31: Mantenimiento preventivo y correctivo del PC
A32: 2024-I | B32: INT FOOD SERVICES CORP S.A | F32: Pasante | H32: Apoyo en la plataforma de E-Training APPRENDER
A33: 2024-II | B33: INT FOOD SERVICES CORP S.A | F33: Pasante | H33: Apoyo en la plataforma de E-Training APPRENDER y capapcitacion del personal sobre manejo de la misma
A35: 5. INFORMACIÓN ADICIONAL (LOGROS RELEVANTES, HABILIDADES, ETC.)
A36: AÑO | B36: INSTITUCIÓN | F36: LOGRO O HECHO RELEVANTE | H36: DETALLE DEL LOGRO O HECHO RELEVANTE
B41: Atentamente,
B45: =DATOS!C6 -> VALLEJOS ALMACHI MARLON VINICIO
B46: NOMBRE Y FIRMA ESTUDIANTE

Sheet 1. PLAN MARCO
C1: INSTITUTO SUPERIOR TECNOLÓGICO DE TURISMO Y PATRIMONIO YAVIRAC | N1: DS-010203-4
C2: MACROPROCESO 01 DOCENCIA
C3: PROCESO 02 PROCESO DE FORMACIÓN PRÁCTICA EN EL ENTORNO LABORAL REAL - FORMACIÓN DUAL
C4: FORMATO 03 PLAN MARCO DE FORMACIÓN
A6: NOMBRE(S) DE ESTUDIANTE(S): | D6: =DATOS!C6 -> VALLEJOS ALMACHI MARLON VINICIO | I6: PERÍODO: | L6: 2025-II
A7: CARRERA: | D7: =DATOS!C8 -> DESARROLLO DE SOFTWARE | I7: NIVEL: | L7: TERCERO
A8: EMPRESA FORMADORA: | D8: =DATOS!C36 -> INSTITUTO DE CAPACITACIÓN Y ESPECIALIZACIÓN AMAUTA-TECH S.A.S. B.I.C. | I8: HORAS DE FORMACIÓN PRÁCTICA: | L8: 480
A9: DIRECCIÓN EMPRESA | D9: =DATOS!C39 -> CLEMENTE CONCHA Numero: OE-758 Intersección: PASAJE E | I9: NÚCLEO ESTRUCTURANTE: | L9: DESARROLLO WEB - BACK- END
A10: NIVELES DE LOGRO ESPERADO
A11: 1: CONOCIMIENTOS BÁSICOS: El estudiante de la carrera dual debe familiarizarse con los contenidos y relaciones del área, de tal forma que pueda nombrarlos y diferenciarlos.
A12: 2: CONOCIMIENTOS: El estudiante de la carrera dual se debe formar en las competencias del área hasta el punto que las pueda aclarar y pueda dar información sobre las mismas.
A13: 3: PARTICIPACION EN LOS PROCEDIMIENTOS: El estudiante de la carrera dual debe adquirir las suficientes capacidades prácticas de tal forma que pueda realizar las tareas o pueda preparar su ejecución.
A14: 4: VALORACIÓN O ELABORACIÓN PROPIA DE PROCEDIMIENTOS DE TRABAJO: El estudiante de la carrera dual se debe formar en la aplicación práctica de tal forma que pueda realizar o elaborar las tareas sin indicaciones y además pueda evaluar una tarea de acuerdo a su criterio.
A16: OBJETIVOS DE LA FASE PRÁCTICA: Desarrollar aplicaciones web tanto del lado del cliente como del servidor utilizando lenguajes de programación web y aplicando algoritmos de búsqueda, ordenamiento, numéricos, estadísticos y criptográficos y Aplicaciones para dispositivos móviles orientados a satisfacer necesidades empresariales y tecnológicas específicas, aplicando buenas prácticas de programación.
A17: OBJETIVOS DE APRENDIZAJE: Al finalizar la fase práctica, el/la estudiante estará en capacidad de:
A18: No. | B18: Resultados de aprendizaje | E18: Nivel de Logro esperado | I18: Nivel real alcanzado | J18: Tareas laborales de aprendizaje a realizar para alcanzar el objetivo | L18: Puesto de aprendizaje (área o departamento de la empresa) | M18: No. de semanas de trabajo | N18: Responsable del puesto de aprendizaje
E19: (ponga una X en el número correspondiente)
E20: 1 | F20: 2 | G20: 3 | H20: 4 | I20: =AVERAGE(I21:I33) -> 3.4615385
A21: 1 | B21: Diseña una servicio web consumible por un cliente web | H21: X | I21: =IF(E21="X",1,IF(F21="X",2,IF(G21="X",3,IF(H21="X",4,0)))) -> 4 | J21: DESARROLLO DE SERVICIOS WEB BACKEND | L21: DESARROLLO | M21: 9 | N21: Ing. Mauricio Tamayo
A22: 2 | B22: Genera con éxito una API REST lista para su consumo. | G22: X | I22: =IF(E22="X",1,IF(F22="X",2,IF(G22="X",3,IF(H22="X",4,0)))) -> 3 | J22: CREACION Y CONSUMO DE API REST
A23: 3 | B23: Implementa capas de protección a un servico web en base a los estándares de seguridad necesarios. | H23: X | I23: =IF(E23="X",1,IF(F23="X",2,IF(G23="X",3,IF(H23="X",4,0)))) -> 4 | J23: APLICACIONS DE SEGURIDAD BASICA
A24: 4 | B24: Genera ideas de negocios innovadoras pertinentes al entorno local y global | G24: X | I24: =IF(E24="X",1,IF(F24="X",2,IF(G24="X",3,IF(H24="X",4,0)))) -> 3 | J24: PROPUESTAS DE MEJORAS FUNCIONALES
A25: 5 | B25: Comprender las diferentes plataformas y herramientas disponibles para la programación de aplicaciones móviles | H25: X | I25: =IF(E25="X",1,IF(F25="X",2,IF(G25="X",3,IF(H25="X",4,0)))) -> 4 | J25: USO DE HERRAMIENTAS Y PLATAFORMAS
A26: 6 | B26: Aplica los conceptos de la técnologia movil nativa | G26: X | I26: =IF(E26="X",1,IF(F26="X",2,IF(G26="X",3,IF(H26="X",4,0)))) -> 3 | J26: APLICACION DE CONCEPTOS BASICOS | L26: DESARROLLO | N26: Ing. Mauricio Tamayo
A27: 7 | B27: Implementa estándares y buenas prácticas durante el desarrollo de una aplicación móvil nativa | H27: X | I27: =IF(E27="X",1,IF(F27="X",2,IF(G27="X",3,IF(H27="X",4,0)))) -> 4 | J27: IMPLEMENTACION DE BUENAS PRACTICAS
A28: 8 | B28: Desarrolla un aplicación móvil plenamente funcional mediante el uso de un lenguaje de programación móvil nativo. | G28: X | I28: =IF(E28="X",1,IF(F28="X",2,IF(G28="X",3,IF(H28="X",4,0)))) -> 3 | J28: IMPLEMENTACION DE FUNCIONALIDADES
A29: 9 | B29: Compara y escoje la metodología de trabajo con la que prefiere trabajar para desarrollar un proyecto en software | H29: X | I29: =IF(E29="X",1,IF(F29="X",2,IF(G29="X",3,IF(H29="X",4,0)))) -> 4 | J29: METODOLOGIAS DE TRABAJO
A30: 10 | B30: Establece los roles, responsabilidades y funciones de los participantes o artefactos de la metodología ágil | G30: X | I30: =IF(E30="X",1,IF(F30="X",2,IF(G30="X",3,IF(H30="X",4,0)))) -> 3 | J30: CUMPLIMIENTO DE ROLES
A31: 11 | B31: Organiza y ejecuta los eventos de metodología ágil para el desarrollo del proyecto | G31: X | I31: =IF(E31="X",1,IF(F31="X",2,IF(G31="X",3,IF(H31="X",4,0)))) -> 3 | J31: ORGANIZACION Y EJECUCION DE TAREAS | L31: INNOVACION | N31: Ing. Mauricio Tamayo
A32: 12 | B32: Utiliza técnicas y herramientas ágiles para el desarrollo del proyecto de software. | H32: X | I32: =IF(E32="X",1,IF(F32="X",2,IF(G32="X",3,IF(H32="X",4,0)))) -> 4 | J32: HERRAMIENTAS MODERNIZADAS
A33: 13 | B33: Integra lo desarrollado en el ciclo actual al producto completo (General) y define cambios de mejora continua para el próximo ciclo de desarrollo | G33: X | I33: =IF(E33="X",1,IF(F33="X",2,IF(G33="X",3,IF(H33="X",4,0)))) -> 3 | J33: MEJORA CONTINUA DEL SISTEMA
B34: Tutor Académico del ISTY
B35: Nombre: | C35: Raúl Alejandro Paz Mundial | I35: Nombre: | J35: Mónica Patricia Bustán Gaona
B36: Firma: _________________________________________________ | I36: Firma:_________________________________________________

Sheet 2. PLAN DE ROTACION
C1: INSTITUTO SUPERIOR TECNOLÓGICO DE TURISMO Y PATRIMONIO YAVIRAC | L1: DS-010204-4
C2: MACROPROCESO 01 DOCENCIA
C3: PROCESO 02 PROCESO DE FORMACIÓN PRÁCTICA EN EL ENTORNO LABORAL REAL - FORMACIÓN DUAL
C4: FORMATO 04 PLAN DE APRENDIZAJE PRÁCTICO Y DE ROTACIÓN
A6: NOMBRE(S) DEL ESTUDIANTE(S): | C6: =DATOS!C6 -> VALLEJOS ALMACHI MARLON VINICIO
A7: CARRERA: | C7: =DATOS!C8 -> DESARROLLO DE SOFTWARE | D7: NIVEL: | E7: TERCERO
A8: EMPRESA FORMADORA: | C8: =DATOS!C36 -> INSTITUTO DE CAPACITACIÓN Y ESPECIALIZACIÓN AMAUTA-TECH S.A.S. B.I.C. | D8: HORAS DE FORMACIÓN PRÁCTICA: | E8: 480
A9: NÚCLEO ESTRUCTURANTE: | C9: DESARROLLO WEB - BACK- END | D9: PERÍODO LECTIVO: | E9: 2025-II
A11: # | B11: Resultados de aprendizaje | D11: Puesto de aprendizaje (área o departamento de la empresa) | E11: DICIEMBRE | J11: ENERO
E12: S1 | F12: S2 | G12: S3 | H12: S4 | I12: S5 | J12: S6 | K12: S7 | L12: S8
E13: 1 - 4 | F13: 45999 | G13: 15-19 | H13: 22-26 | I13: 29-31 | J13: 5- 9 | K13: 12-16 | L13: 19-23
A14: 1 | B14: Diseña una servicio web consumible por un cliente web | D14: TICS | E14: X | F14: x | L14: Defensa de Proyecto empresarial
A15: 2 | B15: Genera con éxito una API REST lista para su consumo. | G15: x
A16: 3 | B16: Implementa capas de protección a un servico web en base a los estándares de seguridad necesarios. | G16: x | H16: x
A17: 4 | B17: Genera ideas de negocios innovadoras pertinentes al entorno local y global | H17: x | I17: x
A18: 5 | B18: Comprender las diferentes plataformas y herramientas disponibles para la programación de aplicaciones móviles | H18: x | I18: x
A19: 6 | B19: Aplica los conceptos de la técnologia movil nativa | D19: DESARROLLO | J19: x
A20: 7 | B20: Implementa estándares y buenas prácticas durante el desarrollo de una aplicación móvil nativa | K20: x
A21: 8 | B21: Desarrolla un aplicación móvil plenamente funcional mediante el uso de un lenguaje de programación móvil nativo. | L21: x
A22: 9 | B22: Compara y escoje la metodología de trabajo con la que prefiere trabajar para desarrollar un proyecto en software | J22: x
A23: 10 | B23: Establece los roles, responsabilidades y funciones de los participantes o artefactos de la metodología ágil | K23: x
A24: 11 | B24: Organiza y ejecuta los eventos de metodología ágil para el desarrollo del proyecto | D24: INNOVACION | J24: x
A25: 12 | B25: Utiliza técnicas y herramientas ágiles para el desarrollo del proyecto de software. | K25: x
A26: 13 | B26: Integra lo desarrollado en el ciclo actual al producto completo (General) y define cambios de mejora continua para el próximo ciclo de desarrollo | K26: x | L26: x
A27: COMPETENCIAS NECESARIAS
A28: CONOCIMIENTOS TEÓRICOS | D28: PROCEDIMENTALES | H28: ACTITUDINALES
A29: Desarrollo de aplicaciones aplicando arquitectura cliente - servidor | D29: Manejo de procesos, lenguajes de programación y frameworks | H29: Proactividad, creatividad, analítico
B34: Tutor Académico del ISTY | D34: Tutor Empresarial de la Empresa Formadora
B35: Nombre: | C35: Raúl Alejandro Paz Mundial | D35: Nombre: | E35: Mónica Patricia Bustán Gaona
B36: Firma: _________________________________________________ | D36: Firma:_________________________________________________

Sheet 3. Registro de Asistencia
C1: INSTITUTO SUPERIOR TECNOLÓGICO DE TURISMO Y PATRIMONIO YAVIRAC | J1: 010205
C2: MACROPROCESO 01 DOCENCIA
C3: PROCESO 02 PROCESO DE FORMACIÓN PRÁCTICA EN EL ENTORNO LABORAL REAL - FORMACIÓN DUAL
C4: FORMATO 05 ACTA DE ASISTENCIA
A6: EMPRESA FORMADORA: | C6: =DATOS!C36 -> INSTITUTO DE CAPACITACIÓN Y ESPECIALIZACIÓN AMAUTA-TECH S.A.S. B.I.C. | G6: CARRERA: | H6: =DATOS!C8 -> DESARROLLO DE SOFTWARE
A7: TUTOR(A) ACADÉMICO: | C7: =DATOS!C16 -> Ing. Diego Yanez | G7: PERÍODO ACADÉMICO: | H7: =DATOS!C19 -> 2025-II
A8: TUTOR(A) EMPRESARIAL: | C8: =DATOS!C38 -> Mauricio Tamayo | G8: NIVEL: | H8: =DATOS!C9 -> TERCER
A9: NOMBRE DEL ESTUDIANTE: | C9: =DATOS!C6 -> VALLEJOS ALMACHI MARLON VINICIO | G9: NÚCLEO ESTRUCTURANTE: | H9: DESARROLLO WEB - BACK- END
A10: E-MAIL INSTITUCIONAL: | C10: =DATOS!C10 -> mva.vallejos@yavirac.edu.ec | G10: TELÉFONO DE EMERGENCIA: | H10: =DATOS!H13 -> 0987355363
A11: TELÉFONO / MÓVIL: | C11: =DATOS!C11 -> 0999294011 | G11: CONTACTO DE EMERGENCIA: | H11: =DATOS!E13 -> Mamá
A12: CÉDULA: | C12: =DATOS!C7 -> 1722586631 | G12: TIPO DE SANGRE: | H12: =DATOS!E12 -> O+
A14: N° | B14: Fecha | C14: Hora Ingreso | D14: Almuerzo | E14: Hora Salida | F14: Horas al día | G14: Firma estudiante | H14: Observaciones:
A15: 1 | B15: 45985 | C15: 08H30 | D15: 12H30 - 13H30 | E15: 17H30 | F15: 8 | H15: S/N
A16: 2 | B16: 45986 | C16: 08H30 | D16: 12H30 - 13H30 | E16: 17H30 | F16: 8 | H16: S/N
A17: 3 | B17: 45987 | C17: 08H30 | D17: 12H30 - 13H30 | E17: 17H30 | F17: 8 | H17: S/N
A18: 4 | B18: 45988 | C18: 08H30 | D18: 12H30 - 13H30 | E18: 17H30 | F18: 8 | H18: S/N
A19: 5 | B19: 45989 | C19: 08H30 | D19: 12H30 - 13H30 | E19: 17H30 | F19: 8 | H19: S/N
A20: 6 | B20: 45992 | C20: 08H30 | D20: 12H30 - 13H30 | E20: 17H30 | F20: 8 | H20: S/N
A21: 7 | B21: 45993 | C21: 08H30 | D21: 12H30 - 13H30 | E21: 17H30 | F21: 8 | H21: S/N
A22: 8 | B22: 45994 | C22: 08H30 | D22: 12H30 - 13H30 | E22: 17H30 | F22: 8 | H22: S/N
A23: 9 | B23: 45995 | C23: 08H30 | D23: 12H30 - 13H30 | E23: 17H30 | F23: 8 | H23: S/N
A24: 10 | B24: 45999 | C24: 08H30 | D24: 12H30 - 13H30 | E24: 17H30 | F24: 8 | H24: S/N
A25: 11 | B25: 46000 | C25: 08H30 | D25: 12H30 - 13H30 | E25: 17H30 | F25: 8 | H25: S/N
A26: 12 | B26: 46001 | C26: 08H30 | D26: 12H30 - 13H30 | E26: 17H30 | F26: 8 | H26: S/N
... A56: 42 | B56: 46045 | C56: 08H36 | D56: 12H30 - 13H36 | E56: 17H36 | F56: 8 | H56: S/N
A57: 43 | B57: 01/12/2025-23/01/2026 | C57: - | D57: - | E57: - | F57: 144 | H57: HORAS AUTÓNOMAS
C58: TOTAL HORAS FASE PRÁCTICA: | F58: 480

Sheet 4. Informe de Aprendizaje
C1: INSTITUTO SUPERIOR TECNOLÓGICO DE TURISMO Y PATRIMONIO YAVIRAC | AA1: DS-010206
C2: MACROPROCESO 01 DOCENCIA
C3: PROCESO 02 PROCESO DE FORMACIÓN PRÁCTICA EN EL ENTORNO LABORAL REAL - FORMACIÓN DUAL
C4: FORMATO 06 BITÁCORA DE APRENDIZAJE DE FASE PRÁCTICA
A6: EMPRESA FORMADORA: | D6: =DATOS!C36 -> INSTITUTO DE CAPACITACIÓN Y ESPECIALIZACIÓN AMAUTA-TECH S.A.S. B.I.C. | N6: NIVEL: | S6: =DATOS!C9 -> TERCER
A7: ESTUDIANTE: | D7: =DATOS!C6 -> VALLEJOS ALMACHI MARLON VINICIO | N7: CICLO ACADÉMICO: | S7: =DATOS!C19 -> 2025-II
A8: CÉDULA: | D8: =DATOS!C7 -> 1722586631 | N8: F. INICIO FASE PRÁCTICA | S8: =DATOS!B30 -> 45985 | X8: F. FIN FASE PRÁCTICA | Z8: =DATOS!B31 -> 46045
A9: TUTOR(A) ACADÉMICO | D9: =DATOS!C16 -> Ing. Diego Yanez | N9: NÚCLEO ESTRUCTURANTE: | S9: DESARROLLO WEB - BACK- END
A10: TUTOR(A) EMPRESARIAL | D10: =DATOS!C38 -> Mauricio Tamayo | N10: CARRERA | S10: =DATOS!C8 -> DESARROLLO DE SOFTWARE
A12: OBJETIVO DEL NÚCLEO ESTRUCTURANTE PARA LA FASE PRÁCTICA
A13: =IF(S6="PRIMERO",DATOS!T69,IF(S6="SEGUNDO",DATOS!T70,IF(S6="TERCERO",DATOS!T71,IF(S6="CUARTO",DATOS!T72,DATOS!T73)))) -> Aplica los conceptos de la técnología móvil híbrida
A15: INFORME DE APRENDIZAJE DE LA FASE PRÁCTICA
A16: SEMANA | B16: FECHA | D16: PUESTO DE APRENDIZAJE | H16: ACTIVIDADES REALIZADAS | T16: ACTIVIDADES AUTÓNOMAS
A17: 1 | B17: 24/11/2025 - 28/11/2025 | D17: Desarrollador backend | H17: Analisis de requerimientos del sistema | T17: Investigacion sobre AIS , REST
A18: 2 | B18: 01/12/2025 - 04/12/2025 | D18: Desarrollador backend | H18: Creacion del proyecto | T18: Revision de patrones de diseño backend
A19: 3 | B19: 08/12/2025 - 13/12/2025 | D19: Desarrollador backend | H19: Implementacion de la logica del negocio | T19: Pruebas locales de endpoints
A20: 4 | B20: 15/12/2025 - 19/12/2025 | D20: Desarrollador backend | H20: Implementacion de control de estados y procesos | T20: Optimizacion de consultas
A21: 5 | B21: 22/12/2025 - 26/12/2025 | D21: Desarrollador backend | H21: pruebas funcionales del sistema backend | T21: Revision de logs y errores
A22: 6 | B22: 29/12/2025 - 02/01/2026 | D22: Desarrollador backend | H22: Integracion de modulos backend | T22: Practicas de pruebas con herramientas como posman
A23: 7 | B23: 05/01/2026 - 09/01/2026 | D23: Desarrollador backend | H23: Mejora de rendimiento del backend | T23: Analisis de mejoras del sistema
A24: 8 | B24: 12/01/2026 - 16/01/2026 | D24: Desarrollador backend | H24: Documentación DTOS y pull request | T24: Inventigacion sobre el manejo de Git Hub
A25: 9 | B25: 19/01/2026 - 23/01/2026 | D25: Desarrollador backend | H25: Ajustes finales y entrega | T25: Revision general del proyecto
A26: Reflexión sobre el aprendizaje alcanzado de las actividades realizadas en la empresa formadora | D26: Durante la fase practica fortaleci mis coonocimientos en la implementacion de APIS | Q26: Observaciones de la empresa formadora sobre el desempeño del estudiante: | T26: Ninguna

Sheet 5. Evaluacion-Empresarial (NUEV
F1: INSTITUTO SUPERIOR TECNOLÓGICO DE TURISMO Y PATRIMONIO YAVIRAC | Y1: DS-010207
F2: MACROPROCESO 01 DOCENCIA
F3: PROCESO 02 PROCESO DE FORMACIÓN PRÁCTICA EN EL ENTORNO LABORAL REAL - FORMACIÓN DUAL
F4: FORMATO 07 INFORME DE EVALUACIÓN POR PARTE DE LA ENTIDAD FORMADORA
A6: EMPRESA FORMADORA: | F6: =DATOS!C36 -> INSTITUTO DE CAPACITACIÓN Y ESPECIALIZACIÓN AMAUTA-TECH S.A.S. B.I.C. | N6: NIVEL: | R6: =DATOS!C9 -> TERCER
A7: ESTUDIANTE: | F7: =DATOS!C6 -> VALLEJOS ALMACHI MARLON VINICIO | N7: CICLO ACADÉMICO: | R7: =DATOS!C19 -> 2025-II
A8: CÉDULA: | F8: =DATOS!C7 -> 1722586631 | N8: F. INICIO FASE PRÁCTICA | R8: =DATOS!B30 -> 45985 | V8: F. FIN FASE PRÁCTICA | X8: =DATOS!B31 -> 46045
A9: TUTOR(A) ACADÉMICO | F9: =DATOS!C16 -> Ing. Diego Yanez | N9: N. ESTRUCTURANTE: | R9: DESARROLLO WEB - BACK- END
A10: TUTOR(A) EMPRESARIAL | F10: =DATOS!C38 -> Mauricio Tamayo | N10: CARRERA | R10: =DATOS!C8 -> DESARROLLO DE SOFTWARE
A12: OBJETIVO DEL NÚCLEO ESTRUCTURANTE PARA LA FASE PRÁCTICA
A13: =IF(R6="PRIMERO",DATOS!T69,IF(R6="SEGUNDO",DATOS!T70,IF(R6="TERCERO",DATOS!T71,IF(R6="CUARTO",DATOS!T72,DATOS!T73)))) -> Aplica los conceptos de la técnología móvil híbrida
B15: EVALUACIÓN DE DESEMPEÑO | I15: NOTA (10 PUNTOS) | L15: DEFENSA PROYECTO TUTOR EMPRESARIAL | P15: Excelente | Q15: Bueno | R15: Regular | S15: Deficiente | T15: NOTA PARCIAL
B16: Logro de Objetivos de Aprendizaje | I16: 9
B17: Desempeño en los puestos de trabajo y actividades asignadas (Plan de rotación) | I17: 9 | L17: CRITERIOS | P17: 4 | Q17: 3 | R17: 2 | S17: 1
B18: Capacidad de aplicar los conocimientos en la práctica. | I18: 9 | L18: Presentación en tiempo y forma (formato, normas APA, cronograma) | P18: 4 | T18: 4
B19: Capacidad de comunicación oral y escrita. | I19: 9 | L19: Calidad de la presentación (uso ayudas técnicas y audiovisuales,etc.) | P19: 4 | T19: 4
B20: Capacidad de investigación, aprender y actualizarse permanentemente | I20: 9 | L20: Dominio del contenido | P20: 4 | T20: 4
B21: Capacidad creativa. | I21: 9 | L21: Claridad y precisión en la exposición | P21: 4 | T21: 4
B22: Capacidad para identificar, plantear y resolver problemas. | I22: 9 | L22: Satisfacción de la Empresa Formadora | P22: 4 | T22: 4
B23: Capacidad de trabajo en equipo y capacidades interpersonales | I23: 10 | L23: Nota Parcial de la Defensa del Proyecto: | T23: =SUM(T18:T22) -> 20
B24: Valoración y respecto por la diversidad y multiculturalidad. | I24: 10 | L24: Nota Final de la Defensa del Proyecto: | T24: =T23*10/20 -> 10
B25: Habilidad para trabajar en forma autónoma. | I25: 10 | L25: Nota ponderada sobre 3 puntos: | T25: =T24*0.3 -> 3
B28: PROMEDIO | I28: =AVERAGE(I16:I27) -> 9.3 | L28: NOTA FINAL EMPRESA | P28: =SUM(I29,T25) -> 9.51
B29: Nota ponderada sobre 7 puntos | I29: =I28*0.7 -> 6.51
B32: COMENTARIOS / OBSERVACIONES:

Sheet 6. Evaluación Instituto (NUEVO)
F2: INSTITUTO SUPERIOR TECNOLÓGICO DE TURISMO Y PATRIMONIO YAVIRAC | AB2: DS -010208
F3: MACROPROCESO 01 DOCENCIA
F4: PROCESO 02 PROCESO DE FORMACIÓN PRÁCTICA EN EL ENTORNO LABORAL REAL - FORMACIÓN DUAL
F5: FORMATO 08 INFORME DE EVALUACIÓN POR PARTE DEL INSTITUTO
A7: EMPRESA FORMADORA: | F7: =DATOS!C36 -> INSTITUTO DE CAPACITACIÓN Y ESPECIALIZACIÓN AMAUTA-TECH S.A.S. B.I.C. | R7: NIVEL: | W7: =DATOS!C9 -> TERCER
A8: ESTUDIANTE: | F8: =DATOS!C6 -> VALLEJOS ALMACHI MARLON VINICIO | R8: CICLO ACADÉMICO: | W8: =DATOS!C19 -> 2025-II
A9: CÉDULA: | F9: =DATOS!C7 -> 1722586631 | R9: F. INICIO FASE PRÁCTICA | W9: =DATOS!B30 -> 45985 | Y9: F. FIN FASE PRÁCTICA | AA9: =DATOS!B31 -> 46045
A10: TUTOR(A) ACADÉMICO | F10: =DATOS!C16 -> Ing. Diego Yanez | R10: N. ESTRUCTURANTE: | W10: DESARROLLO WEB - BACK- END
A11: TUTOR(A) EMPRESARIAL | F11: =DATOS!C38 -> Mauricio Tamayo | R11: CARRERA | W11: =DATOS!C8 -> DESARROLLO DE SOFTWARE
A13: OBJETIVO DEL NÚCLEO ESTRUCTURANTE PARA LA FASE PRÁCTICA
A14: =IF(W7="PRIMERO",DATOS!T69,IF(W7="SEGUNDO",DATOS!T70,IF(W7="TERCERO",DATOS!T71,IF(W7="CUARTO",DATOS!T72,DATOS!T73)))) -> Aplica los conceptos de la técnología móvil híbrida
A16: DEFENSA PROYECTO TUTOR ACADÉMICO | E16: Excelente | F16: Bueno | G16: Regular | H16: Deficiente | I16: NOTA PARCIAL | K16: TEMA | Q16: PARÁMETROS PROYECTO EMPRESARIAL | AA16: NOTA
A17: CRITERIOS | E17: 4 | F17: 3 | G17: 2 | H17: 1 | K17: =DATOS!A24 -> EXPLORACIÓN DE LA ARQUITECTURA DEL PROYECTO YAVIGESTIÓN | Q17: 1.Proactividad, independencia y compromiso demostrado en la elaboración del proyecto | AA17: 9
A18: Presentación en tiempo y forma (formato, normas APA, cronograma) | E18: 4 | I18: 3 | Q18: 2. Plazo y calidad en la entrega de documentos | AA18: 9
A19: Calidad de la presentación (uso ayudas técnicas y audiovisuales,etc.) | E19: 4 | I19: 4 | Q19: 3. Cumplimiento de parametros en el proyecto empresarial escrito | AA19: 9
A20: Dominio del contenido | E20: 4 | I20: 4 | Q20: 4. Desarrollo del proyecto en profundidad y aporte a la solución del problema | AA20: 9
A21: Claridad y precisión en la exposición | E21: 4 | I21: =SUM(E21:H21) -> 4 | Q21: 5. Cumplimiento de requerimientos / objetivos planteados al inicio del proyecto | AA21: 9
A22: Satisfacción de la Empresa Formadora | E22: 4 | I22: =SUM(E22:H22) -> 4 | Q22: 6. Uso de metodología científica y aplicación de normas bibliográficas | AA22: 9
A23: Nota Parcial de la Defensa del Proyecto: | I23: =SUM(I18:I22) -> 19 | Q23: 7. Aporte al proyecto acorde al nivel académico | AA23: 9
A24: Nota Final de la Defensa del Proyecto: | I24: =I23*10/20 -> 9.5 | Q24: Promedio Parcial del Proyecto Empresarial: | AA24: =AVERAGE(AA17:AA23) -> 9
A25: Nota ponderada sobre 3 puntos | I25: =I24*0.3 -> 2.85 | Q25: Nota ponderada sobre 7 puntos | AA25: =AA24*0.7 -> 6.3
A27: EVALUACIÓN FINAL CONSOLIDADO EMPRESA - INSTITUTO | P27: COMENTARIOS / OBSERVACIONES:
A28: EVALUACIÓN EMPRESA | H28: EVALUACIÓN INSTITUTO
A29: ='5. Evaluacion-Empresarial (NUEV'!P28 -> 9.51 | H29: 9.5
A31: PROMEDIO FINAL FASE PRÁCTICA: | H31: =(+A29*0.5)+(H29*0.5) -> 9.505

Sheet Hoja de Ruta
A10: REGISTRO DE VISITAS INSTITUCIONALES O EMPRESARIALES/TUTORÍAS FASES PRÁCTICAS
A11: HOJA DE RUTA
A13: NOMBRE DEL DOCENTE:
A14: N° | B14: Intitución/Empresa a la que se visita | C14: Asunto | D14: Contacto | E14: Teléfono | F14: Firma Institución/Empresa | G14: Fecha | H14: Hora Salida del ISTY | I14: Hora llegada a reunión | J14: Hora Finalización de Reunión | K14: OBSERVACIONES
A15: 1
A16: 2
A17: 3
A18: 4
A19: 5
A20: 6
A21: 7
A22: 8
A23: 9
A24: 10

Sheet SOLICITUD ALUMNO
A10: INSTITUTO SUPERIOR TECNOLÓGICO DE TURISMO Y PATRIMONIO "YAVIRAC"
A11: Dirección: García Moreno S-435 y Ambato
A12: Quito - Ecuador
E14: Quito DM., | F14: =TODAY() -> 46208
A16: Magíster
A17: Gabriela Coral
A18: COORDINADORA DE VINCULACIÓN DEL IST YAVIRAC
A19: Presente.-
A21: De mis consideraciones:
A23: Después de expresarle un caluroso saludo y éxitos en sus funciones, me permito remitirle la siguiente Solicitud:
A25: Yo, | B25: =DATOS!C6 -> VALLEJOS ALMACHI MARLON VINICIO | E25: con C.C. Nro. | F25: =DATOS!C7 -> 1722586631 | G25: estudiante de la carrera de
A26: =DATOS!C8 -> DESARROLLO DE SOFTWARE | D26: me dirijo a Ud., para solicitarle de la manera más comedida se confiera
A27: un certificado de haber realizado el Servicio a la Comunidad y las Prácticas pre profesionales, mismo que es
A28: necesario presentarlo como requisito para la defensa del Proyecto de Titulación contemplado en la Coordinación
A29: de Titulación del Instituto Superior Tecnológico de Turismo y Patrimonio Yavirac.
A31: Por la favorable atención que se digne dar al presente, le anticipo mis sentidos agradecimientos.
A34: Atentamente,
A35: FIRMA COLOR AZUL (ESTE DOCUMENTO SE DEBE ENVIAR SOLAMENTE SI YA CUMPLIÓ CON PRÁCTICAS Y VINCULACIÓN)
A41: =DATOS!C6 -> VALLEJOS ALMACHI MARLON VINICIO
A42: =DATOS!C7 -> 1722586631
A43: =DATOS!C10 -> mva.vallejos@yavirac.edu.ec
A44: =DATOS!C11 -> 0999294011
